Workbook

Sheet تعليمات
A1: استمارة تقييم الزيارة الصفية Classroom Visit Evaluation Form مدرسة عبدالله بن ناصر الحلقة الثانية بنين Abdullah Bin Nasser Cycle 2 Boys School معلم Teacher
A2: دليل الاستخدام السريع Quick User Guide
A3: 1) يعبئ المعلم بياناته في أعلى ورقة التقييم الذاتي. 1) The teacher fills in the information at the top of the self-evaluation sheet.
A4: 2) يختار درجة من 1 إلى 5 لكل مؤشر في عمود: اختياري (1-5). 2) Select a score from 1 to 5 for each indicator in the Optional Score column.
A5: 3) يظهر تلقائيا الوصف المختار والمثال المساعد بحسب الدرجة. 3) The selected descriptor and supporting example appear automatically according to the score.
A6: 4) يكتب المعلم في عمود: دليلي من الممارسة، شاهدا مختصرا على أدائه. 4) The teacher writes brief evidence of practice in the “My Evidence from Practice” column.
A7: 5) في ورقة التحليل التلقائي يظهر المتوسط العام ومستوى التفتيش (جيد/جيد جدا/مقبول). 5) The analysis sheet shows the overall average and inspection level (Good / Very Good / Acceptable).
A8: 6) في ورقة الخطة التلقائية تظهر أهم 3 أولويات مع توصية فورية وإجراء تنفيذي. 6) The automatic plan shows the top three priorities with an immediate recommendation and action step.
A9: 7) تستخدم لوحة المدرسة لتجميع نتائج عدة معلمين يدويا لأغراض المتابعة المدرسية. 7) The school dashboard is used to manually consolidate results for several teachers for follow-up purposes.
A12: مفتاح الدرجات Scoring Key
A13: 1 = يحتاج إلى تحسين | 2 = منخفض | 3 = جيد | 4 = يفوق التوقعات | 5 = يفوق التوقعات بشكل ملحوظ 1 = Needs Improvement | 2 = Low | 3 = Good | 4 = Exceeds Expectations | 5 = Significantly Exceeds Expectations
A16: مديرة المدرسة School Principal
A17: شيخة أحمد حسن الحساني Shaikha Ahmed Hasan Al Hassani

Sheet لوحة المدرسة
A1: استمارة تقييم الزيارة الصفية Classroom Visit Evaluation Form مدرسة عبدالله بن ناصر الحلقة الثانية بنين Abdullah Bin Nasser Cycle 2 Boys School معلم Teacher
A5: اسم المعلم Teacher Name | B5: المادة Subject | C5: رقم الأوراكل Oracle Number | D5: تاريخ الزيارة Visit Date | E5: المتوسط Average | F5: المستوى Level | G5: مجموع الأولويات Total Priorities | I5: ملخص
A6: =التقييم!B5 -> رشا احمد محمود عبدالسلام | B6: =التقييم!B6 -> الفنون البصرية | C6: =التقييم!B7 -> 282439 | D6: =التقييم!E6 -> 13/5/2026 | E6: =التقييم!E3 -> 4.63 | F6: =التقييم!G3 -> جيد جدا Very Good | G6: =التقييم!I3 -> 0 | I6: عدد المعلمين - جيد | J6: =COUNTIF(E6:E25,"جيد") -> 0
I7: عدد المعلمين - جيد جدا | J7: =COUNTIF(F6:F25,"جيد جدا") -> 0

Sheet التقييم
A1: استمارة تقييم الزيارة الصفية Classroom Visit Evaluation Form مدرسة عبدالله بن ناصر الحلقة الثانية بنين Abdullah Bin Nasser Cycle 2 Boys School معلم Teacher
A2: التعلم الواقعي Realistic Learning
D3: المتوسط العام Overall Average | E3: =IF(COUNT(H10:H33)=0,"",ROUND(SUM(H10:H33)/COUNT(H10:H33),2)) -> 4.63 | F3: المستوى التفتيشي Inspection Level | G3: =IF(E3="","",IF(E3>=4.3,"جيد جدا Very Good",IF(E3>=3.5,"جيد Good",IF(E3>=2.5,"مقبول Acceptable","يحتاج إلى دعم Needs Support")))) -> جيد جدا Very Good | H3: عدد الأولويات Number of Priorities | I3: =COUNT($J$10:$J$33) -> 0
A5: اسم المعلم Teacher Name | B5: رشا احمد محمود عبدالسلام | D5: الصف والشعبة Grade and Section | E5: ثامن متقدم | G5: عدد الطلاب Number of Students | H5: 20 | K5: عدد أصحاب الهمم Number of Students of Determination | L5: 0
A6: المادة Subject | B6: الفنون البصرية | D6: التاريخ Date | E6: 13/5/2026 | G6: عدد الحضور Attendance | H6: 20 | K6: عنوان الدرس Lesson Title
A7: رقم الأوراكل Oracle Number | B7: 282439 | D7: الحصة Period | E7: الثانية | G7: عدد الغياب Absences | H7: =H5-H6 -> 0 | K7: ناتج التعلم Learning Outcome
A9: المجال Domain | B9: المؤشر Indicator | C9: 1 يحتاج إلى تحسين 1 Needs Improvement | D9: 2 منخفض 2 Low | E9: 3 جيد 3 Good | F9: 4 يفوق التوقعات 4 Exceeds Expectations | G9: 5 يفوق التوقعات بشكل ملحوظ 5 Significantly Exceeds Expectations | H9: اختياري (1-5) Optional (1-5) | I9: الوصف المختار Selected Description | J9: ترتيب الأولوية Priority Order | K9: الشواهد Evidence | L9: التغذية الراجعة Feedback
A10: التخطيط والتهيئة الحافزة Planning and Motivating Introduction | B10: إعداد خطة درس متكاملة Preparing an Integrated Lesson Plan | C10: الخطة غير واضحة أو منسوخة ولا ترتبط بالنواتج. The plan is unclear or copied and not linked to outcomes. | D10: توجد خطة لكن التنفيذ غير متسق مع الزمن والنواتج. A plan exists, but implementation is not aligned with time and outcomes. | E10: الخطة واضحة وتدعم تحقيق نواتج التعلم. The plan is clear and supports learning outcomes. | F10: الخطة جاذبة ومنظمة وتخدم معظم المتعلمين. The plan is engaging, organized, and serves most learners. | G10: الخطة إبداعية ومترابطة وتحقق تعلم جميع المتعلمين. The plan is creative, coherent, and supports all learners. | H10: 5 | I10: =IF(H10="","",CHOOSE(H10,C10,D10,E10,F10,G10)) -> الخطة إبداعية ومترابطة وتحقق تعلم جميع المتعلمين. The plan is creative, coherent, and supports all learners. | J10: =IF(OR($H10="",$H10>3),"",COUNTIF($H$10:$H$33,"<"&$H10)+COUNTIF($H$10:$H10,$H10)) | K10: خطة درس مكتوبة - توزيع زمني - ربط الأنشطة بالنواتج - تحضير يومي/أسبوعي Time allocation - Activity/outcome alignment - Written lesson plan - Daily/weekly preparation | L10: التخطيط كان جاذبًا ومنظمًا ويدعم تعلم غالبية الطلبة بصورة فعالة. | M10: أستخدم خطة سابقة كما هي دون تعديل للحصة الحالية. I use a previous plan as it is without adapting it to the current lesson. | N10: أكتب أهدافا وأنشطة، لكن بعض الأنشطة لا ينفذ فعليا داخل الحصة. I write objectives and activities, but some activities are not actually implemented in the lesson. | O10: أحدد ناتجا مثل: يفسر الطالب المفهوم، وأخصص نشاطا مناسبا له. I identify an outcome, such as: the student explains the concept, and allocate a suitable activity for it. | P10: أوزع وقت الحصة بين تمهيد ونشاط وتطبيق وتقويم ويشارك معظم الطلبة. I distribute lesson time among introduction, activity, application, and assessment, with most students participating. | Q10: أبني الحصة على مشروع أو مهمة أصيلة يقودها الطلبة وتصل بالجميع للناتج. I build the lesson around a project or authentic task led by students that enables everyone to reach the outcome.
B11: تقديم تهيئة حافزة Providing a Motivating Introduction | C11: لا أقدم تهيئة للدرس. No lesson introduction is provided. | D11: أقدم تهيئة غير مناسبة أو ضعيفة الارتباط بالدرس. The introduction is unsuitable or weakly linked to the lesson. | E11: أقدم تهيئة مناسبة تساعد على بدء التعلم. A suitable introduction helps start learning. | F11: أقدم تهيئة محفزة مرتبطة بموضوع الدرس. A motivating introduction is linked to the lesson topic. | G11: أقدم تهيئة مشوقة تثير الفضول والتفكير من بداية الحصة. An engaging introduction stimulates curiosity and thinking from the start. | H11: 5 | I11: =IF(H11="","",CHOOSE(H11,C11,D11,E11,F11,G11)) -> أقدم تهيئة مشوقة تثير الفضول والتفكير من بداية الحصة. An engaging introduction stimulates curiosity and thinking from the start. | J11: =IF(OR($H11="",$H11>3),"",COUNTIF($H$10:$H$33,"<"&$H11)+COUNTIF($H$10:$H11,$H11)) | K11: صورة/فيديو للتهيئة - أسئلة افتتاحية - نشاط تمهيدي - ملاحظات صفية Image/video - Opening questions - Starter activity - Classroom notes | L11: التهيئة كانت مشوقة ومحفزة وأسهمت في إثارة الفضول منذ بداية الحصة. | M11: أبدأ الشرح مباشرة دون تمهيد. I start teaching directly without an introduction. | N11: أطرح سؤالا عاما لا يقود إلى موضوع الدرس. I ask a general question that does not lead to the lesson topic. | O11: أعرض سؤالا أو صورة مرتبطة تمهد للموضوع. I show a related question or image that prepares for the topic. | P11: أستخدم موقفا أو فيديو قصيرا يثير النقاش حول فكرة الدرس. I use a situation or short video that stimulates discussion around the lesson idea. | Q11: أبدأ بقصة أو مشكلة واقعية تدفع الطلبة لتوقع موضوع الدرس واستكشافه. I start with a story or real-life problem that leads students to predict and explore the lesson topic.
B12: عرض نواتج التعلم وبناء الوعي بها Presenting and Building Awareness of Learning Outcomes | C12: لا أعرض نواتج التعلم على المتعلمين. Learning outcomes are not presented to learners. | D12: أعرض النواتج دون التأكد من فهم المتعلمين لها. Outcomes are presented without checking learners’ understanding. | E12: أعرض النواتج ويظهر فهم مناسب لدى غالبية المتعلمين. Outcomes are presented and most learners show appropriate understanding. | F12: أشرح النواتج وأناقشها وتبقى حاضرة أثناء التعلم. Outcomes are explained, discussed, and remain present during learning. | G12: يستنتج المتعلمون النواتج ويعبرون عنها بوضوح أثناء الحصة. Learners infer and express the outcomes clearly during the lesson. | H12: 5 | I12: =IF(H12="","",CHOOSE(H12,C12,D12,E12,F12,G12)) -> يستنتج المتعلمون النواتج ويعبرون عنها بوضوح أثناء الحصة. Learners infer and express the outcomes clearly during the lesson. | J12: =IF(OR($H12="",$H12>3),"",COUNTIF($H$10:$H$33,"<"&$H12)+COUNTIF($H$10:$H12,$H12)) | K12: نواتج التعلم على السبورة/العرض - أسئلة مناقشة - تصوير لوحات الصف Outcomes on board/display - Discussion questions - Photos of classroom boards | L12: استنتج الطلبة نواتج التعلم وعبّروا عنها بوضوح خلال الحصة. | M12: لا يعرف الطلبة ماذا سيتعلمون اليوم. Students do not know what they will learn today. | N12: أكتب الهدف على السبورة فقط دون شرح معناه. I write the objective on the board only without explaining its meaning. | O12: أقرأ النواتج وأوضح المطلوب بلغة مناسبة للطلبة. I read the outcomes and explain the expected learning in student-friendly language. | P12: أعود إلى النواتج أثناء الأنشطة وأسأل: هل حققنا هذا الناتج؟ I revisit the outcomes during activities and ask: Have we achieved this outcome? | Q12: من خلال النشاط التمهيدي يصوغ الطلبة ما سيتعلمونه ويقيسون تقدمهم نحوه. Through the starter activity, students formulate what they will learn and measure their progress toward it.
A13: الكفاية العلمية وتحقيق التعلم Subject Competence and Learning Achievement | B13: التمكن العلمي في المادة Subject Knowledge Mastery | C13: أحتاج إلى تطوير واضح في المحتوى العلمي المرتبط بالدرس. Clear development is needed in lesson-related subject content. | D13: أمتلك معرفة جزئية بالمحتوى ولا أتعمق فيه بما يكفي. There is partial knowledge of content without sufficient depth. | E13: أمتلك معرفة كافية تمكّنني من شرح المفاهيم بدقة. Knowledge is sufficient to explain concepts accurately. | F13: أمتلك فهما عميقا للمحتوى وأربطه بأمثلة وتطبيقات متنوعة. There is deep understanding of content linked to varied examples and applications. | G13: أمتلك عمقا معرفيا ومهاريا عاليا وأقود المتعلمين إلى فهم متقدم. There is high knowledge and skill depth leading learners to advanced understanding. | H13: 5 | I13: =IF(H13="","",CHOOSE(H13,C13,D13,E13,F13,G13)) -> أمتلك عمقا معرفيا ومهاريا عاليا وأقود المتعلمين إلى فهم متقدم. There is high knowledge and skill depth leading learners to advanced understanding. | J13: =IF(OR($H13="",$H13>3),"",COUNTIF($H$10:$H$33,"<"&$H13)+COUNTIF($H$10:$H13,$H13)) | K13: محتوى العرض - إجابات المعلم - أعمال الطلبة - نتائج التعلم Presentation content - Teacher responses - Student work - Learning results | L13: أظهرت المعلمة عمقًا معرفيًا ومهاريًا عاليًا وقادت الطلبة إلى فهم متقدم. | M13: أتردد عند الإجابة عن أسئلة الطلبة الأساسية. I hesitate when answering students’ basic questions. | N13: أشرح المفهوم بصورة صحيحة لكن بصورة سطحية. I explain the concept correctly but superficially. | O13: أوضح المفهوم بدقة وأجيب عن أغلب الاستفسارات المرتبطة به. I explain the concept accurately and answer most related questions. | P13: أربط الفكرة بأمثلة من الحياة وبمفاهيم سابقة ولاحقة. I link the idea to real-life examples and previous and future concepts. | Q13: أوسع التعلم إلى تطبيقات متقدمة واستقصاء ومقارنات تعمق الفهم. I extend learning to advanced applications, inquiry, and comparisons that deepen understanding.
B14: مراعاة التسلسل المنطقي للمعرفة Considering the Logical Sequence of Knowledge | C14: أعرض المحتوى بصورة عشوائية تربك المتعلمين. Content is presented randomly and confuses learners. | D14: أراعي التسلسل أحيانا لكن بصورة غير كافية. Sequencing is considered sometimes but not sufficiently. | E14: أعرض المحتوى بتسلسل منطقي مناسب. Content is presented in an appropriate logical sequence. | F14: أعرض المحتوى بتسلسل يعزز الفهم والاستيعاب. Content is sequenced to enhance understanding and comprehension. | G14: أبني التعلم بتسلسل يقود إلى التحليل والتفكير العالي. Learning is sequenced to lead to analysis and higher-order thinking. | H14: 5 | I14: =IF(H14="","",CHOOSE(H14,C14,D14,E14,F14,G14)) -> أبني التعلم بتسلسل يقود إلى التحليل والتفكير العالي. Learning is sequenced to lead to analysis and higher-order thinking. | J14: =IF(OR($H14="",$H14>3),"",COUNTIF($H$10:$H$33,"<"&$H14)+COUNTIF($H$10:$H14,$H14)) | K14: خطة الدرس - تسلسل الشرائح - الأعمال الصفية Lesson plan - Slide sequence - Classroom work | L14: بُني المحتوى بتسلسل منطقي قاد إلى التحليل والتفكير العالي. | M14: أنتقل بين الأفكار دون تمهيد أو رابط واضح. I move between ideas without preparation or a clear link. | N14: أقدم بعض الأفكار بترتيب جيد وأخرى دون تمهيد كاف. I present some ideas in good order and others without sufficient preparation. | O14: أبدأ من التمهيد ثم المفهوم ثم التطبيق ثم التقويم. I start with the introduction, then the concept, then application, then assessment. | P14: أنتقل من البسيط إلى المركب مع ربط كل خطوة بالتي قبلها. I move from simple to complex while linking each step to the previous one. | Q14: أستخدم التسلسل للوصول إلى الاستنتاج والمقارنة وتكوين الرأي. I use sequencing to reach inference, comparison, and opinion formation.
B15: تحقيق التكامل بين المادة والمواد الأخرى Integrating the Subject with Other Subjects | C15: لا أوظف أي ربط بين المادة وبقية المواد. No connections are made between this subject and other subjects. | D15: أحقق ربطا محدودا بين أجزاء المادة أو مع مواد أخرى. Limited links are made within the subject or with other subjects. | E15: أحقق ترابطا جزئيا داعما للتعلم. Partial connections support learning. | F15: أحقق ترابطا واضحا وكافيا بين المادة والمواد الأخرى. Clear and sufficient links are made between the subject and other subjects. | G15: أمكن المتعلمين من بناء روابط هادفة تعزز الفهم الأكاديمي. Learners build meaningful links that enhance academic understanding. | H15: 5 | I15: =IF(H15="","",CHOOSE(H15,C15,D15,E15,F15,G15)) -> أمكن المتعلمين من بناء روابط هادفة تعزز الفهم الأكاديمي. Learners build meaningful links that enhance academic understanding. | J15: =IF(OR($H15="",$H15>3),"",COUNTIF($H$10:$H$33,"<"&$H15)+COUNTIF($H$10:$H15,$H15)) | K15: أنشطة تكاملية - مشاريع بينية - خطط مشتركة Integrated activities - Cross-curricular projects - Joint plans | L15: أُتيحت فرص لبناء روابط معرفية هادفة عززت الفهم الأكاديمي. | M15: أقدم المفاهيم بمعزل عن بقية المواد. I present concepts separately from other subjects. | N15: أشير أحيانا إلى فكرة قريبة من مادة أخرى دون توظيف فعلي. I sometimes refer to an idea from another subject without actual application. | O15: أربط مهارة القراءة في الدرس العلمي مثلا بفهم المصطلحات. I link reading skills in a science lesson, for example, to understanding terminology. | P15: أصمم نشاطا يربط الرياضيات بالعلوم أو العربية بالدراسات الاجتماعية. I design an activity linking mathematics with science or Arabic with social studies. | Q15: يقارن الطلبة بين مفاهيم من مواد متعددة ويوظفونها في مشروع واحد. Students compare concepts from multiple subjects and use them in one project.
B16: ربط التعلم بالبيئة المحلية والواقع Linking Learning to the Local Environment and Real Life | C16: لا أربط التعلم بالواقع أو البيئة المحلية. Learning is not linked to real life or the local environment. | D16: أقدم ربطا سطحيا أو عاما بالواقع. A superficial or general link to real life is provided. | E16: أربط التعلم بالواقع بصورة محدودة مناسبة. Learning is linked to real life in a limited but suitable way. | F16: أربط التعلم بالواقع والبيئة المحلية بصورة واضحة وكافية. Learning is clearly and sufficiently linked to real life and the local environment. | G16: أجعل التعلم ذا معنى من خلال مشكلات وأمثلة من حياة المتعلمين. Learning becomes meaningful through problems and examples from learners’ lives. | H16: 5 | I16: =IF(H16="","",CHOOSE(H16,C16,D16,E16,F16,G16)) -> أجعل التعلم ذا معنى من خلال مشكلات وأمثلة من حياة المتعلمين. Learning becomes meaningful through problems and examples from learners’ lives. | J16: =IF(OR($H16="",$H16>3),"",COUNTIF($H$10:$H$33,"<"&$H16)+COUNTIF($H$10:$H16,$H16)) | K16: أمثلة واقعية - صور من البيئة - مشاريع حياتية Real-life examples - Local environment images - Life-related projects | L16: جُعل التعلم ذا معنى من خلال ربطه بمشكلات وأمثلة واقعية من حياة الطلبة. | M16: أشرح المفهوم نظريا فقط. I explain the concept theoretically only. | N16: أذكر مثالا عاما دون أن ينعكس على النشاط. I mention a general example without reflecting it in the activity. | O16: أستخدم مثالا من البيئة المحلية يوضح الفكرة. I use an example from the local environment to clarify the idea. | P16: أطلب من الطلبة تطبيق المفهوم على موقف يواجهونه في حياتهم. I ask students to apply the concept to a situation they face in their lives. | Q16: يصمم الطلبة حلا لمشكلة من واقعهم اعتمادا على ما تعلموه. Students design a solution to a real-life problem based on what they learned.
B17: تقديم الدعم لرفع مستويات التعلم Providing Support to Raise Learning Levels | C17: دعمي محدود ولا يساعد المتعلمين على التحسن. Support is limited and does not help learners improve. | D17: أقدم دعما لبعض المتعلمين فقط. Support is provided to some learners only. | E17: أقدم دعما كافيا لغالبية المتعلمين. Sufficient support is provided to most learners. | F17: أقدم دعما جيدا لمعظم المتعلمين يرفع الأداء والمهارات. Good support raises the performance and skills of most learners. | G17: أقدم دعما فعالا لجميع المتعلمين بحسب احتياجاتهم. Effective support is provided to all learners according to their needs. | H17: 4 | I17: =IF(H17="","",CHOOSE(H17,C17,D17,E17,F17,G17)) -> أقدم دعما جيدا لمعظم المتعلمين يرفع الأداء والمهارات. Good support raises the performance and skills of most learners. | J17: =IF(OR($H17="",$H17>3),"",COUNTIF($H$10:$H$33,"<"&$H17)+COUNTIF($H$10:$H17,$H17)) | K17: خطط علاجية - أنشطة إثرائية - متابعة فردية - سجلات دعم Remedial plans - Enrichment activities - Individual follow-up - Support records | L17: قُدم دعم تعليمي جيد لمعظم الطلبة وأسهم في رفع مستوى أدائهم. | M17: أشرح بنفس الطريقة لجميع الطلبة دون متابعة الفروق. I explain in the same way for all students without following up on differences. | N17: أعيد الشرح لطالب أو اثنين فقط عند الحاجة. I re-explain to one or two students only when needed. | O17: أخصص شرحا إضافيا أو ورقة مساعدة للمجموعة المحتاجة. I provide additional explanation or a support worksheet for the group in need. | P17: أوظف مجموعات مرنة وأنشطة متفاوتة المستوى ودعما مباشرا. I use flexible groups, differentiated activities, and direct support. | Q17: أطبق خططا فردية وإثرائية وعلاجية واضحة وأتابع أثرها على الجميع. I apply clear individual, enrichment, and remedial plans and follow up on their impact for all.
B18: إظهار المتعلمين استيعابا للمعرفة والمفاهيم Learners Demonstrating Understanding of Knowledge and Concepts | C18: لا يظهر المتعلمون استيعابا للمفاهيم المستهدفة. Learners do not show understanding of targeted concepts. | D18: يظهر عدد قليل من المتعلمين استيعابا للمفاهيم. A few learners show understanding of concepts. | E18: يظهر غالبية المتعلمين استيعابا مناسبا للمفاهيم. Most learners show appropriate understanding of concepts. | F18: يظهر معظم المتعلمين استيعابا واضحا ودقيقا للمفاهيم. Most learners show clear and accurate understanding of concepts. | G18: يظهر جميع المتعلمين استيعابا تاما ويطبقون المعرفة في سياقات مختلفة. All learners show full understanding and apply knowledge in different contexts. | H18: 4 | I18: =IF(H18="","",CHOOSE(H18,C18,D18,E18,F18,G18)) -> يظهر معظم المتعلمين استيعابا واضحا ودقيقا للمفاهيم. Most learners show clear and accurate understanding of concepts. | J18: =IF(OR($H18="",$H18>3),"",COUNTIF($H$10:$H$33,"<"&$H18)+COUNTIF($H$10:$H18,$H18)) | K18: أوراق العمل - إجابات الطلبة - نتائج التقويم - منتجات التعلم Worksheets - Student responses - Assessment results - Learning products | L18: أظهر معظم الطلبة استيعابًا واضحًا ودقيقًا للمفاهيم المستهدفة. | M18: لا يستطيع الطلبة تفسير الفكرة بعد الشرح. Students cannot explain the idea after the explanation. | N18: يجيب بعض الطلبة فقط عن أسئلة الفهم الأساسية. Only some students answer basic comprehension questions. | O18: تظهر الإجابات والمهام أن أغلب الطلبة فهموا المفهوم الرئيس. Responses and tasks show that most students understood the main concept. | P18: يشرح معظم الطلبة المفهوم بلغتهم ويطبقونه في نشاط جديد. Most students explain the concept in their own words and apply it in a new activity. | Q18: ينقل جميع الطلبة التعلم إلى مواقف جديدة ويبررون إجاباتهم. All students transfer learning to new situations and justify their answers.
B19: طرح أسئلة واضحة ومتنوعة وتعزيز التفكير العالي Asking Clear and Varied Questions and Promoting Higher-Order Thinking | C19: أسئلتي غير واضحة أو محدودة ولا تنمي التفكير. Questions are unclear or limited and do not develop thinking. | D19: أطرح أسئلة واضحة لكن دون تعزيز فعلي للتفكير العالي. Questions are clear but do not effectively promote higher-order thinking. | E19: أطرح أسئلة متنوعة وأعزز التفكير في مواقف محدودة. Varied questions promote thinking in limited situations. | F19: أطرح أسئلة واضحة ومتنوعة وأعزز التفكير العالي في مواقف مختلفة. Clear and varied questions promote higher-order thinking in different situations. | G19: أطرح أسئلة ثرية مستمرة تجعل المتعلمين مندمجين في التفكير العميق طوال الحصة. Rich ongoing questions keep learners engaged in deep thinking throughout the lesson. | H19: 4 | I19: =IF(H19="","",CHOOSE(H19,C19,D19,E19,F19,G19)) -> أطرح أسئلة واضحة ومتنوعة وأعزز التفكير العالي في مواقف مختلفة. Clear and varied questions promote higher-order thinking in different situations. | J19: =IF(OR($H19="",$H19>3),"",COUNTIF($H$10:$H$33,"<"&$H19)+COUNTIF($H$10:$H19,$H19)) | K19: سجل أسئلة - فيديو الحصة - ملحوظات صفية Question log - Lesson video - Classroom notes | L19: طُرحت أسئلة واضحة ومتنوعة عززت التفكير العالي في مواقف مختلفة. | M19: أكتفي بأسئلة تذكر مباشرة مثل: ما التعريف؟ I limit questions to direct recall, such as: What is the definition? | N19: أنوع بين الشفهي والمباشر لكن دون تحليل أو تفسير. I vary between oral and direct questions but without analysis or explanation. | O19: أستخدم أسئلة لماذا وكيف في موضع واحد من الدرس. I use why and how questions in one part of the lesson. | P19: أستخدم أسئلة مقارنة وتبرير واستنتاج أثناء الشرح والتطبيق. I use comparison, justification, and inference questions during explanation and application. | Q19: يبني الطلبة إجابات مركبة ويناقشون ويبررون ويطرحون أسئلة مضادة. Students build complex answers, discuss, justify, and ask counter-questions.
B20: استخدام لغة سليمة وواضحة Using Clear and Accurate Language | C20: أستخدم لغة غير دقيقة أو غير مناسبة للموقف الصفي. Language is inaccurate or unsuitable for the classroom situation. | D20: أستخدم لغة سليمة وواضحة أحيانا فقط. Clear and accurate language is used only sometimes. | E20: أستخدم لغة سليمة وواضحة في غالبية الموقف الصفي. Clear and accurate language is used in most classroom situations. | F20: أستخدم لغة سليمة وواضحة في جميع فعاليات الحصة. Clear and accurate language is used in all lesson activities. | G20: أمكن المتعلمين أيضا من التعبير بلغة سليمة وواضحة طوال الحصة. Learners are also enabled to express themselves clearly and accurately throughout the lesson. | H20: 4 | I20: =IF(H20="","",CHOOSE(H20,C20,D20,E20,F20,G20)) -> أستخدم لغة سليمة وواضحة في جميع فعاليات الحصة. Clear and accurate language is used in all lesson activities. | J20: =IF(OR($H20="",$H20>3),"",COUNTIF($H$10:$H$33,"<"&$H20)+COUNTIF($H$10:$H20,$H20)) | K20: تسجيل صوتي/مرئي - ملاحظات إشرافية - أعمال كتابية Audio/video recording - Supervisory notes - Written work | L20: استُخدمت لغة سليمة وواضحة في جميع فعاليات الحصة. | M20: تغلب اللغة العامية أو العبارات غير الدقيقة على الشرح. Colloquial language or inaccurate expressions dominate the explanation. | N20: أحافظ على اللغة السليمة في أجزاء من الحصة فقط. I maintain accurate language in parts of the lesson only. | O20: أشرح بلغة سليمة في معظم المواقف مع بعض الهفوات اليسيرة. I explain using accurate language in most situations with minor slips. | P20: أضبط المصطلحات والتعليمات والأسئلة بلغة سليمة واضحة طوال الحصة. I control terminology, instructions, and questions using clear accurate language throughout the lesson. | Q20: أدعم المتعلمين ليجيبوا ويتحاوروا ويكتبوا بلغة سليمة مناسبة. I support learners to answer, discuss, and write using appropriate accurate language.
A21: الاستراتيجيات ومصادر التعلم Strategies and Learning Resources | B21: توظيف استراتيجيات وأنشطة تعليمية فاعلة Employing Effective Teaching Strategies and Activities | C21: أستخدم التعليم المباشر معظم الوقت بما يضعف النمو المعرفي والمهاري. Direct instruction is used most of the time, weakening cognitive and skill development. | D21: أنوع الاستراتيجيات لكن أثرها غير كاف على التعلم. Strategies are varied, but their impact on learning is insufficient. | E21: أوظف استراتيجيات مناسبة تشغل غالبية المتعلمين بالتعلم. Appropriate strategies engage most learners in learning. | F21: أوظف استراتيجيات وأنشطة مؤثرة تعزز نمو معظم المتعلمين. Impactful strategies and activities enhance the growth of most learners. | G21: أوظف استراتيجيات وأنشطة فاعلة ومبتكرة تحقق نموا ملحوظا للجميع. Effective and innovative strategies achieve noticeable growth for all learners. | H21: 4 | I21: =IF(H21="","",CHOOSE(H21,C21,D21,E21,F21,G21)) -> أوظف استراتيجيات وأنشطة مؤثرة تعزز نمو معظم المتعلمين. Impactful strategies and activities enhance the growth of most learners. | J21: =IF(OR($H21="",$H21>3),"",COUNTIF($H$10:$H$33,"<"&$H21)+COUNTIF($H$10:$H21,$H21)) | K21: استراتيجيات مكتوبة - صور الأنشطة - منتجات الطلبة Written strategies - Activity photos - Student products | L21: وُظفت استراتيجيات وأنشطة تعليمية مؤثرة دعمت تعلم معظم الطلبة. | M21: أشرح طوال الحصة دون نشاط حقيقي للطلبة. I explain throughout the lesson without real student activity. | N21: أستخدم نشاطا جماعيا لكن دون وضوح الهدف أو المنتج. I use a group activity but without a clear objective or product. | O21: أوظف التعلم التعاوني أو التعلم النشط بصورة مناسبة للحصة. I use cooperative learning or active learning appropriately for the lesson. | P21: أستخدم حل المشكلات أو المحطات التعليمية ويظهر أثرها على معظم الطلبة. I use problem-solving or learning stations, and their impact appears on most students. | Q21: أبني التعلم على مشروع أو مهمة أدائية أصيلة ترفع مستوى جميع المتعلمين. I build learning around a project or authentic performance task that raises the level of all learners.
B22: توظيف مصادر وموارد تعلم ملائمة Using Appropriate Learning Sources and Resources | C22: أستخدم مصادر غير ملائمة أو غير داعمة للنواتج. Sources are unsuitable or do not support outcomes. | D22: أستخدم مصادر ملائمة لكن بصورة تقليدية محدودة. Sources are suitable but used in a limited traditional way. | E22: أوظف أدوات ووسائط داعمة للتعلم وإشراك غالبية المتعلمين. Tools and media support learning and engage most learners. | F22: أوظف أدوات متنوعة ورقمية تدعم التعلم وتحقق مستوى جيد من التمكين. Varied and digital tools support learning and achieve good empowerment. | G22: أوظف مصادر متنوعة وتفاعلية تشرك جميع المتعلمين بفاعلية عالية. Varied interactive resources engage all learners with high effectiveness. | H22: 4 | I22: =IF(H22="","",CHOOSE(H22,C22,D22,E22,F22,G22)) -> أوظف أدوات متنوعة ورقمية تدعم التعلم وتحقق مستوى جيد من التمكين. Varied and digital tools support learning and achieve good empowerment. | J22: =IF(OR($H22="",$H22>3),"",COUNTIF($H$10:$H$33,"<"&$H22)+COUNTIF($H$10:$H22,$H22)) | K22: عروض - منصات تعليمية - أوراق عمل - أدوات رقمية Presentations - Learning platforms - Worksheets - Digital tools | L22: استُخدمت أدوات ووسائط متنوعة ورقمية دعمت التعلم ورفعت مستوى التمكين. | M22: أعتمد على الكتاب فقط دون وسيط داعم. I rely only on the textbook without a supporting medium. | N22: أستخدم عرضا بسيطا أو ورقة عمل واحدة فقط. I use a simple presentation or one worksheet only. | O22: أستخدم فيديو أو بطاقة أو أداة تساعد على الفهم والمشاركة. I use a video, card, or tool that supports understanding and participation. | P22: أدمج منصة أو نشاطا رقميا وورقة عمل ووسيطا بصريا في الحصة. I integrate a platform or digital activity, a worksheet, and a visual medium in the lesson. | Q22: يوظف الطلبة أدوات رقمية وتفاعلية متعددة لإنتاج تعلمهم وعرضه. Students use multiple digital and interactive tools to produce and present their learning.
B23: مراعاة الفروق الفردية واحتياجات أصحاب الهمم Considering Individual Differences and the Needs of Students of Determination | C23: ممارساتي لا تلبي احتياجات المتعلمين المختلفة. Practices do not meet learners’ different needs. | D23: ألبي احتياجات عدد قليل من المتعلمين بصورة محدودة. The needs of a few learners are met in a limited way. | E23: ألبي احتياجات غالبية المتعلمين بما فيهم أصحاب الهمم. The needs of most learners are met, including students of determination. | F23: أستخدم ممارسات متنوعة تلبي احتياجات معظم المتعلمين. Varied practices meet the needs of most learners. | G23: أستخدم ممارسات متنوعة وفاعلة تلبي احتياجات جميع المتعلمين. Varied and effective practices meet the needs of all learners. | H23: 5 | I23: =IF(H23="","",CHOOSE(H23,C23,D23,E23,F23,G23)) -> أستخدم ممارسات متنوعة وفاعلة تلبي احتياجات جميع المتعلمين. Varied and effective practices meet the needs of all learners. | J23: =IF(OR($H23="",$H23>3),"",COUNTIF($H$10:$H$33,"<"&$H23)+COUNTIF($H$10:$H23,$H23)) | K23: أنشطة متدرجة - خطط فردية - تكييفات - سجلات أصحاب الهمم Differentiated activities - Individual plans - Accommodations - Students of determination records | L23: روعيت الفروق الفردية واحتياجات جميع الطلبة بفاعلية عالية. | M23: أقدم المهمة نفسها والدعم نفسه للجميع دون تكييف. I provide the same task and support to everyone without adaptation. | N23: أعدل مهمة واحدة لطالب أو اثنين فقط عند الحاجة. I modify one task for one or two students only when needed. | O23: أوفر مستويات مختلفة للنشاط أو تعليمات مبسطة عند الحاجة. I provide different activity levels or simplified instructions when needed. | P23: أنوع بين مجموعات مرنة وخيارات تعلم ووسائل مساندة. I vary flexible groups, learning choices, and support tools. | Q23: أصمم تكييفات واضحة ومتابعة دقيقة لكل فئة بما يضمن مشاركتهم جميعا. I design clear accommodations and accurate follow-up for each group to ensure everyone participates.
A24: الإدارة والتفاعل الصفي Classroom Management and Interaction | B24: متابعة امتثال المتعلمين للأنظمة واللوائح Monitoring Learners’ Compliance with Rules and Regulations | C24: أبدأ الحصة دون متابعة الحضور أو الانضباط. The lesson starts without checking attendance or discipline. | D24: أتابع الحضور فقط أو بشكل محدود. Attendance is checked only or in a limited way. | E24: أتابع الحضور والانضباط وأحث على السلوك الإيجابي. Attendance and discipline are monitored and positive behavior is encouraged. | F24: يمتثل المتعلمون للأنظمة واللوائح بصورة واضحة أثناء الحصة. Learners clearly comply with rules and regulations during the lesson. | G24: يعكس انضباط المتعلمين الذاتي قوة العلاقة والاتساق في إدارة الصف. Learners’ self-discipline reflects strong relationships and consistency in classroom management. | H24: 5 | I24: =IF(H24="","",CHOOSE(H24,C24,D24,E24,F24,G24)) -> يعكس انضباط المتعلمين الذاتي قوة العلاقة والاتساق في إدارة الصف. Learners’ self-discipline reflects strong relationships and consistency in classroom management. | J24: =IF(OR($H24="",$H24>3),"",COUNTIF($H$10:$H$33,"<"&$H24)+COUNTIF($H$10:$H24,$H24)) | K24: سجل حضور - قواعد صفية - ملاحظات زيارة Attendance record - Classroom rules - Visit notes | L24: عكس انضباط الطلبة الذاتي قوة العلاقة الصفية وجودة إدارة الصف. | M24: أبدأ مباشرة مع وجود فوضى أو تأخر دون معالجة. I start directly while there is disorder or lateness without addressing it. | N24: أسجل الحضور لكن لا أتابع السلوك داخل الأنشطة. I record attendance but do not follow up on behavior during activities. | O24: أذكر التوقعات وأتابع الالتزام بها أثناء الحصة. I state expectations and monitor commitment to them during the lesson. | P24: تسير الأنشطة بانضباط واضح والطلبة يعرفون التوقعات ويلتزمون بها. Activities run with clear discipline, and students know and follow expectations. | Q24: ينتقل الطلبة بين الأنشطة بسلاسة ويلتزمون ذاتيا دون تدخل كبير. Students move smoothly between activities and self-regulate with little intervention.
B25: تشجيع المشاركة ورفع الدافعية نحو التعلم Encouraging Participation and Raising Motivation Toward Learning | C25: لا أوظف أساليب تعزيز وتحفيز فعالة. Effective reinforcement and motivation methods are not used. | D25: أوظف التحفيز بشكل محدود ويظهر أثره على عدد قليل. Motivation is used in a limited way and affects only a few learners. | E25: أوظف أساليب متنوعة ويظهر دافع مناسب لدى غالبية المتعلمين. Varied methods show appropriate motivation among most learners. | F25: أوظف أساليب متنوعة وفعالة ويظهر دافع عال لدى معظم المتعلمين. Varied and effective methods show high motivation among most learners. | G25: أوظف أساليب محفزة عالية التأثير ويظهر حماس ودافعية لدى جميع المتعلمين. High-impact motivational methods show enthusiasm and motivation among all learners. | H25: 4 | I25: =IF(H25="","",CHOOSE(H25,C25,D25,E25,F25,G25)) -> أوظف أساليب متنوعة وفعالة ويظهر دافع عال لدى معظم المتعلمين. Varied and effective methods show high motivation among most learners. | J25: =IF(OR($H25="",$H25>3),"",COUNTIF($H$10:$H$33,"<"&$H25)+COUNTIF($H$10:$H25,$H25)) | K25: بطاقات/نقاط تحفيز - صور مشاركة - ملاحظات صفية Motivation cards/points - Participation photos - Classroom notes | L25: وُظفت أساليب تحفيزية فعالة أظهرت دافعية مرتفعة لدى معظم الطلبة. | M25: لا أشجع المشاركة أو أعتمد على المتطوعين أنفسهم فقط. I do not encourage participation or rely only on the same volunteers. | N25: أستخدم تشجيعا لفظيا محدودا لا يغير مستوى التفاعل كثيرا. I use limited verbal encouragement that does not greatly change interaction. | O25: أستخدم نقاطا أو تعزيزا لفظيا وأنشطة تشاركية تزيد مشاركة الأغلبية. I use points or verbal reinforcement and participatory activities that increase majority participation. | P25: أخلق منافسة إيجابية ومهاما ممتعة تجعل معظم الطلبة متحمسين. I create positive competition and enjoyable tasks that make most students enthusiastic. | Q25: يتسابق جميع الطلبة للمشاركة ويظهرون حماسا واضحا طوال الحصة. All students compete to participate and show clear enthusiasm throughout the lesson.
B26: إدارة الوقت وتوزيعه على فعاليات التعلم Managing and Distributing Time Across Learning Activities | C26: إدارة الوقت غير منضبطة وتؤثر سلبا على تحقيق النواتج. Time management is uncontrolled and negatively affects outcome achievement. | D26: إدارة الوقت محدودة وتمكن من تحقيق بعض النواتج فقط. Time management is limited and enables only some outcomes. | E26: تضبط بعض فعاليات التعلم زمنيا وتتحقق غالبية النواتج. Some learning activities are timed and most outcomes are achieved. | F26: تضبط فعاليات التعلم زمنيا وتتحقق جميع النواتج المخطط لها. Learning activities are timed and all planned outcomes are achieved. | G26: تدار الحصة بدقة زمنية عالية وتغلق في الوقت المحدد مع تحقق جميع النواتج. The lesson is managed with high timing precision and ends on time with all outcomes achieved. | H26: 5 | I26: =IF(H26="","",CHOOSE(H26,C26,D26,E26,F26,G26)) -> تدار الحصة بدقة زمنية عالية وتغلق في الوقت المحدد مع تحقق جميع النواتج. The lesson is managed with high timing precision and ends on time with all outcomes achieved. | J26: =IF(OR($H26="",$H26>3),"",COUNTIF($H$10:$H$33,"<"&$H26)+COUNTIF($H$10:$H26,$H26)) | K26: توزيع زمني - ملاحظة الحصة - تحقق النواتج Time allocation - Lesson observation - Outcome achievement | L26: أُديرت الحصة بدقة زمنية عالية وتحققت جميع نواتج التعلم. | M26: ينتهي الوقت قبل التطبيق أو التقويم الختامي. Time ends before application or the final assessment. | N26: يستهلك التمهيد أو الشرح وقتا أطول من اللازم. The introduction or explanation takes longer than necessary. | O26: أنجز معظم مراحل الحصة في وقتها مع بعض التفاوت البسيط. I complete most lesson stages on time with minor variation. | P26: يتوزع الوقت بوضوح بين التمهيد والتعلم والتطبيق والتقويم. Time is clearly distributed among introduction, learning, application, and assessment. | Q26: تسير الحصة بسلاسة بمؤقت واضح وإنهاء منظم وتأمل ختامي في الوقت المحدد. The lesson proceeds smoothly with a clear timer, organized closure, and final reflection on time.
A27: التقويم Assessment | B27: استمرارية التقويم بأنواعه المختلفة Continuity of Different Types of Assessment | C27: أطبق نوعا واحدا من التقويم دون استمرارية. One assessment type is applied without continuity. | D27: أطبق نوعين من التقويم لكن دون استمرارية كافية. Two assessment types are applied without sufficient continuity. | E27: أطبق التقويم القبلي والمرحلي والختامي بصورة مناسبة لغالبية المتعلمين. Pre-, formative, and summative assessment are applied appropriately for most learners. | F27: أطبق جميع أنواع التقويم باستمرار ودقة لمعظم المتعلمين. All assessment types are applied continuously and accurately for most learners. | G27: أطبق جميع أنواع التقويم باستمرار عالية ودقة لجميع المتعلمين. All assessment types are applied with high continuity and accuracy for all learners. | H27: 4 | I27: =IF(H27="","",CHOOSE(H27,C27,D27,E27,F27,G27)) -> أطبق جميع أنواع التقويم باستمرار ودقة لمعظم المتعلمين. All assessment types are applied continuously and accurately for most learners. | J27: =IF(OR($H27="",$H27>3),"",COUNTIF($H$10:$H$33,"<"&$H27)+COUNTIF($H$10:$H27,$H27)) | K27: تقويم قبلي - أسئلة مرحلية - Exit ticket - اختبارات قصيرة Pre-assessment - Formative questions - Exit ticket - Short quizzes | L27: طُبقت أنواع التقويم المختلفة باستمرارية ودقة مناسبة لمعظم الطلبة. | M27: أكتفي باختبار أو سؤال ختامي فقط. I rely only on a test or final question. | N27: أبدأ بسؤال قبلي وأنهي بتقويم ختامي دون متابعة أثناء الحصة. I start with a pre-question and end with final assessment without follow-up during the lesson. | O27: أستخدم مدخلا قبليا وأسئلة مرحلية وتقويما ختاميا بسيطا. I use a pre-entry, formative questions, and a simple final assessment. | P27: أجمع أدلة تعلم أثناء الحصة وأعدل التدريس بناء عليها. I collect learning evidence during the lesson and adjust teaching accordingly. | Q27: أتابع تقدم كل متعلم لحظيا وأغير المسار التعليمي بما يضمن تحقق النواتج للجميع. I monitor each learner’s progress in real time and adjust teaching to ensure outcomes are achieved for all.
B28: توظيف أساليب وأدوات فاعلة لقياس التقدم الأكاديمي Using Effective Methods and Tools to Measure Academic Progress | C28: الأدوات التي أستخدمها محدودة ولا تقيس التقدم بدقة. The tools used are limited and do not measure progress accurately. | D28: الأدوات جيدة لكنها تقيس عددا قليلا من المتعلمين أو الجوانب. The tools are good but measure only a few learners or aspects. | E28: أوظف أدوات متنوعة مناسبة لقياس تقدم غالبية المتعلمين. Varied appropriate tools measure the progress of most learners. | F28: أوظف أدوات متميزة ومتنوعة تقيس تقدم معظم المتعلمين بدقة. Distinguished and varied tools accurately measure the progress of most learners. | G28: أوظف أدوات متميزة وشاملة تقيس تقدم جميع المتعلمين بوضوح. Distinguished and comprehensive tools clearly measure the progress of all learners. | H28: 4 | I28: =IF(H28="","",CHOOSE(H28,C28,D28,E28,F28,G28)) -> أوظف أدوات متميزة ومتنوعة تقيس تقدم معظم المتعلمين بدقة. Distinguished and varied tools accurately measure the progress of most learners. | J28: =IF(OR($H28="",$H28>3),"",COUNTIF($H$10:$H$33,"<"&$H28)+COUNTIF($H$10:$H28,$H28)) | K28: Rubrics - Quizzes - بطاقات ملاحظة - منتجات تعلم Rubrics - Quizzes - Observation cards - Learning products | L28: استُخدمت أدوات تقويم متميزة ومتنوعة قاست تقدم معظم الطلبة بدقة. | M28: أعتمد على سؤال شفهي عام أو ورقة واحدة فقط. I rely on a general oral question or only one worksheet. | N28: أستخدم أداة مناسبة لكن على عينة محدودة من الطلبة. I use a suitable tool but on a limited sample of students. | O28: أستخدم rubrics أو بطاقات ملاحظة أو اختبارات قصيرة مناسبة للحصة. I use rubrics, observation cards, or short quizzes suitable for the lesson. | P28: أجمع بين قوائم رصد وأسئلة رقمية ومنتجات تعلم لقياس التقدم. I combine checklists, digital questions, and learning products to measure progress. | Q28: أبني نظاما واضحا يجمع أدلة متعددة لكل متعلم ويظهر تقدمه بدقة. I build a clear system that collects multiple evidence for each learner and accurately shows progress.
B29: تقديم التغذية الراجعة الموجهة Providing Targeted Feedback | C29: لا أقدم تغذية راجعة مناسبة للموقف التعليمي. Feedback appropriate to the learning situation is not provided. | D29: أقدم تغذية راجعة محدودة لا تساعد إلا قليلا. Feedback is limited and helps only slightly. | E29: أقدم تغذية راجعة موجهة تحسن أداء غالبية المتعلمين. Targeted feedback improves the performance of most learners. | F29: أقدم تغذية راجعة فعالة لمعظم المتعلمين وتتيح فرصا للتصحيح والتحسين. Effective feedback supports most learners and provides chances for correction and improvement. | G29: أقدم تغذية راجعة عالية الأثر تنعكس بوضوح على أعمال جميع المتعلمين. High-impact feedback is clearly reflected in all learners’ work. | H29: 5 | I29: =IF(H29="","",CHOOSE(H29,C29,D29,E29,F29,G29)) -> أقدم تغذية راجعة عالية الأثر تنعكس بوضوح على أعمال جميع المتعلمين. High-impact feedback is clearly reflected in all learners’ work. | J29: =IF(OR($H29="",$H29>3),"",COUNTIF($H$10:$H$33,"<"&$H29)+COUNTIF($H$10:$H29,$H29)) | K29: أعمال مصححة - تعليقات كتابية/شفهية - قبل/بعد التحسين Corrected work - Written/oral comments - Before/after improvement | L29: قُدمت تغذية راجعة عالية الأثر انعكست بوضوح على تحسين أداء الطلبة. | M29: أصحح بالإشارة إلى الخطأ فقط دون توضيح. I correct by pointing to the error only without explanation. | N29: أعطي ملاحظة عامة مثل: انتبه أكثر، دون تحديد ما المطلوب. I give a general comment such as “Pay more attention” without specifying what is required. | O29: أوضح موضع الخطأ وكيف يمكن تحسينه في المهمة الحالية. I explain where the error is and how it can be improved in the current task. | P29: أمنح الطالب فرصة لإعادة المحاولة بعد الملاحظة وأتابع التحسن. I give the student a chance to retry after feedback and follow up on improvement. | Q29: يستخدم الطلبة التغذية الراجعة مباشرة لتحسين المنتج وتظهر قفزة واضحة في الأداء. Students use feedback immediately to improve the product, and a clear performance leap appears.
B30: إتاحة الفرصة للتقييم الذاتي وتقييم الأقران Providing Opportunities for Self-Assessment and Peer Assessment | C30: لا أتيح للمتعلمين فرصا للتقييم الذاتي. Learners are not given opportunities for self-assessment. | D30: أتيح الفرصة لعدد محدود من المتعلمين فقط. The opportunity is provided to a limited number of learners only. | E30: أتيح فرصا متنوعة لغالبية المتعلمين لقياس مدى تحقق النواتج. Varied opportunities are provided for most learners to measure outcome achievement. | F30: أتيح فرصا متنوعة لمعظم المتعلمين للتقييم الذاتي وتقييم بعضهم بعضا. Varied opportunities are provided for most learners for self- and peer assessment. | G30: أجعل التقييم الذاتي وتقييم الأقران ممارسة ثابتة وفاعلة لجميع المتعلمين. Self- and peer assessment become consistent and effective practices for all learners. | H30: 5 | I30: =IF(H30="","",CHOOSE(H30,C30,D30,E30,F30,G30)) -> أجعل التقييم الذاتي وتقييم الأقران ممارسة ثابتة وفاعلة لجميع المتعلمين. Self- and peer assessment become consistent and effective practices for all learners. | J30: =IF(OR($H30="",$H30>3),"",COUNTIF($H$10:$H$33,"<"&$H30)+COUNTIF($H$10:$H30,$H30)) | K30: بطاقات تقييم ذاتي - Peer assessment - قوائم تحقق Self-assessment cards - Peer assessment - Checklists | L30: جُعل التقييم الذاتي وتقييم الأقران ممارسة فاعلة لمعظم الطلبة. | M30: أكتفي أنا بالحكم على التعلم دون إشراك الطلبة. I judge learning myself without involving students. | N30: أطلب من طالب أو مجموعة قليلة مراجعة أدائهم سريعا. I ask one student or a small group to review their performance quickly. | O30: أستخدم بطاقة بسيطة أو إشارة مرورية ليقيس أغلب الطلبة تعلمهم. I use a simple card or traffic-light strategy so most students can measure their learning. | P30: يوظف الطلبة قائمة تحقق ويقدمون تغذية راجعة لأقرانهم بصورة منظمة. Students use a checklist and provide feedback to peers in an organized way. | Q30: يمتلك جميع الطلبة أدوات واضحة للتقييم الذاتي وتقييم الأقران ويستخدمونها بفاعلية. All students have clear tools for self- and peer assessment and use them effectively.
A31: جودة حياة المتعلمين Learners’ Wellbeing | B31: تهيئة بيئة مادية ونفسية ملائمة للتعلم Preparing a Suitable Physical and Psychological Learning Environment | C31: أبدأ الحصة دون تهيئة البيئة المادية أو النفسية. The lesson starts without preparing the physical or psychological environment. | D31: أهيئ البيئة بشكل جزئي فقط. The environment is prepared only partially. | E31: أتحقق من تهيئة مكونات البيئة المادية والنفسية المناسبة للتعلم. The appropriate physical and psychological components are checked. | F31: أهيئ البيئة بصورة جيدة ويظهر استعداد معظم المتعلمين للتعلم. The environment is well prepared and most learners show readiness to learn. | G31: أهيئ البيئة بصورة عالية الجودة ويظهر استعداد جميع المتعلمين للتعلم. The environment is prepared with high quality and all learners show readiness to learn. | H31: 5 | I31: =IF(H31="","",CHOOSE(H31,C31,D31,E31,F31,G31)) -> أهيئ البيئة بصورة عالية الجودة ويظهر استعداد جميع المتعلمين للتعلم. The environment is prepared with high quality and all learners show readiness to learn. | J31: =IF(OR($H31="",$H31>3),"",COUNTIF($H$10:$H$33,"<"&$H31)+COUNTIF($H$10:$H31,$H31)) | K31: صور الصف - ترتيب البيئة - قواعد صفية - جاهزية الأدوات Classroom photos - Environment arrangement - Classroom rules - Tool readiness | L31: تهيأت البيئة المادية والنفسية بجودة عالية وأسهمت في جاهزية الطلبة للتعلم. | M31: الصف غير مهيأ والأدوات غير جاهزة والطلبة غير مستقرين. The classroom is not prepared, tools are not ready, and students are not settled. | N31: تتوفر بعض عناصر البيئة المناسبة لكن ليست كلها. Some suitable environmental elements are available, but not all. | O31: أجهز المقاعد والمواد والقواعد النفسية الداعمة قبل البدء. I prepare seating, materials, and supportive psychological rules before starting. | P31: تبدو البيئة منظمة وآمنة ومحفزة ويبدأ معظم الطلبة بسرعة. The environment appears organized, safe, and motivating, and most students start quickly. | Q31: تجمع البيئة بين التنظيم والأمان والتحفيز والانتماء ويبدأ الجميع باستعداد واضح. The environment combines organization, safety, motivation, and belonging, and everyone starts with clear readiness.
B32: تعزيز الاتصال والتواصل مع المتعلمين Enhancing Communication and Interaction with Learners | C32: العلاقة مع المتعلمين غير فاعلة وتؤثر سلبا على السلوك. The relationship with learners is ineffective and negatively affects behavior. | D32: توجد علاقة جيدة لكن أثرها محدود على عدد قليل من المتعلمين. There is a good relationship, but its impact is limited to a few learners. | E32: أقيم علاقات فاعلة تؤثر إيجابا على سلوك غالبية المتعلمين. Effective relationships positively influence the behavior of most learners. | F32: تسود علاقات احترام وتواصل بناء تنعكس إيجابا على معظم المتعلمين. Respectful relationships and constructive communication positively affect most learners. | G32: أحافظ على علاقات احترام وثقة وتواصل بناء ينعكس إيجابا على جميع المتعلمين ورفاهيتهم. Respect, trust, and constructive communication positively affect all learners and their wellbeing. | H32: 5 | I32: =IF(H32="","",CHOOSE(H32,C32,D32,E32,F32,G32)) -> أحافظ على علاقات احترام وثقة وتواصل بناء ينعكس إيجابا على جميع المتعلمين ورفاهيتهم. Respect, trust, and constructive communication positively affect all learners and their wellbeing. | J32: =IF(OR($H32="",$H32>3),"",COUNTIF($H$10:$H$33,"<"&$H32)+COUNTIF($H$10:$H32,$H32)) | K32: استبانات طلبة - ملاحظات صفية - شواهد تواصل Student surveys - Classroom notes - Communication evidence | L32: سادت علاقات احترام وثقة وتواصل بنّاء انعكست إيجابًا على رفاهية الطلبة. | M32: يغلب الطابع الرسمي أو التوتر على التفاعل الصفي. The classroom interaction is dominated by formality or tension. | N32: أتواصل بود مع بعض الطلبة فقط أو في مواقف محدودة. I communicate warmly with some students only or in limited situations. | O32: أستمع للطلبة وأحترم آراءهم وأدعمهم بصورة منتظمة. I listen to students, respect their opinions, and support them regularly. | P32: يسود الحوار والاحترام والثقة في أغلب الموقف الصفي. Dialogue, respect, and trust prevail in most classroom situations. | Q32: يشعر جميع الطلبة بالأمان والتقدير ويطلبون الدعم بثقة ويشاركون بارتياح. All students feel safe and valued, ask for support confidently, and participate comfortably.
B33: تحفيز ومكافأة التقدم الأكاديمي والسلوك الإيجابي Motivating and Rewarding Academic Progress and Positive Behavior | C33: لا أوظف أساليب لتعزيز التقدم الأكاديمي أو السلوك الإيجابي. Methods to reinforce academic progress or positive behavior are not used. | D33: أستخدم أساليب محدودة دون أثر واضح. Limited methods are used without clear impact. | E33: أوظف أساليب متنوعة يظهر أثرها على غالبية المتعلمين. Varied methods show impact on most learners. | F33: أوظف أساليب تحفيز وتعزيز فعالة يظهر أثرها على معظم المتعلمين. Effective motivation and reinforcement methods show impact on most learners. | G33: أوظف أساليب عالية التأثير تعزز الدافعية والمسؤولية والتنافس الإيجابي لدى الجميع. High-impact methods enhance motivation, responsibility, and positive competition among all. | H33: 5 | I33: =IF(H33="","",CHOOSE(H33,C33,D33,E33,F33,G33)) -> أوظف أساليب عالية التأثير تعزز الدافعية والمسؤولية والتنافس الإيجابي لدى الجميع. High-impact methods enhance motivation, responsibility, and positive competition among all. | J33: =IF(OR($H33="",$H33>3),"",COUNTIF($H$10:$H$33,"<"&$H33)+COUNTIF($H$10:$H33,$H33)) | K33: سجلات تحفيز - شهادات - صور تكريم - ملاحظات Motivation records - Certificates - Recognition photos - Notes | L33: وُظفت أساليب تحفيز وتعزيز عالية التأثير دعمت الدافعية والمسؤولية والتنافس الإيجابي. | M33: لا توجد عبارات أو أنظمة واضحة للتقدير والتعزيز. There are no clear appreciation or reinforcement phrases or systems. | N33: أشجع أحيانا لكن دون اتساق أو متابعة الأثر. I encourage sometimes but without consistency or follow-up on impact. | O33: أستخدم شهادات أو نقاطا أو تعزيزات لفظية منتظمة تزيد الانضباط والمشاركة. I use certificates, points, or regular verbal reinforcement that increases discipline and participation. | P33: أربط التعزيز بالتقدم الحقيقي والسلوك الإيجابي ويظهر الأثر على معظم الطلبة. I link reinforcement to real progress and positive behavior, and the impact appears on most students. | Q33: يتحول التعزيز إلى ثقافة صفية ترفع الإنجاز والمسؤولية والتنافس الإيجابي بين الجميع. Reinforcement becomes a classroom culture that raises achievement, responsibility, and positive competition among all.

Sheet التحليل
A1: تحليل نتائج استمارة تقييم الزيارات الصفية Analysis of Classroom Visit Evaluation Results مدرسة عبدالله بن ناصر الحلقة الثانية بنين Abdullah Bin Nasser Cycle 2 Boys School معلم Teacher
B2: اسم المعلم Teacher Name | C2: رقم الأوراكل Oracle Number | E2: المادة Subject | F2: تاريخ الزيارة Visit Date | G2: الصف والشعبة Grade / Section | H2: الحصة Period
B3: =التقييم!B5 -> رشا احمد محمود عبدالسلام | C3: =التقييم!B7 -> 282439 | E3: =التقييم!B6 -> الفنون البصرية | F3: =التقييم!E6 -> 13/5/2026 | G3: =التقييم!E5 -> ثامن متقدم | H3: =التقييم!E7 -> الثانية
B5: المؤشر العام Overall Indicator | C5: القيمة | E5: المجال Domain | F5: متوسط المجال Domain Average | G5: قراءة سريعة Quick Reading
B6: متوسط الأداء العام Overall Performance Average | C6: =التقييم!E3 -> 4.63 | E6: التخطيط والتهيئة الحافزة Planning and Motivational Introduction | F6: =IF(COUNT(التقييم!H10:H12)=0,"",ROUND(SUM(التقييم!H10:H12)/COUNT(التقييم!H10:H12),2)) -> 5 | G6: =IF(F6="","",IF(F6>=4.3,"Exceeds Expectations",IF(F6>=3.5,"Good",IF(F6>=2.5,"Low","Needs Improvement")))) -> Exceeds Expectations
B7: المستوى التفتيشي Inspection Level | C7: =التقييم!G3 -> جيد جدا Very Good | E7: الكفاية العلمية وتحقيق التعلم Subject Competence and Learning Achievement | F7: =IF(COUNT(التقييم!H13:H20)=0,"",ROUND(SUM(التقييم!H13:H20)/COUNT(التقييم!H13:H20),2)) -> 4.5 | G7: =IF(F7="","",IF(F7>=4.3,"Exceeds Expectations",IF(F7>=3.5,"Good",IF(F7>=2.5,"Low","Needs Improvement")))) -> Exceeds Expectations
B8: عدد المؤشرات ذات الأولوية (<=3) Number of Priority Indicators (<=3) | C8: =التقييم!I3 -> 0 | E8: الاستراتيجيات ومصادر التعلم Strategies and Learning Resources | F8: =IF(COUNT(التقييم!H21:H23)=0,"",ROUND(SUM(التقييم!H21:H23)/COUNT(التقييم!H21:H23),2)) -> 4.33 | G8: =IF(F8="","",IF(F8>=4.3,"Exceeds Expectations",IF(F8>=3.5,"Good",IF(F8>=2.5,"Low","Needs Improvement")))) -> Exceeds Expectations
B9: نسبة المؤشرات 4-5 Percentage of Indicators Rated 4–5 | C9: =IF(COUNT(التقييم!H10:H33)=0,"",ROUND(COUNTIFS(التقييم!H10:H33,">=4",التقييم!H10:H33,"<=5")/COUNT(التقييم!H10:H33),2)) -> 1 | E9: الإدارة والتفاعل الصفي Classroom Management and Interaction | F9: =IF(COUNT(التقييم!H24:H26)=0,"",ROUND(SUM(التقييم!H24:H26)/COUNT(التقييم!H24:H26),2)) -> 4.67 | G9: =IF(F9="","",IF(F9>=4.3,"Exceeds Expectations",IF(F9>=3.5,"Good",IF(F9>=2.5,"Low","Needs Improvement")))) -> Exceeds Expectations
E10: التقويم Assessment | F10: =IF(COUNT(التقييم!H27:H30)=0,"",ROUND(SUM(التقييم!H27:H30)/COUNT(التقييم!H27:H30),2)) -> 4.5 | G10: =IF(F10="","",IF(F10>=4.3,"Exceeds Expectations",IF(F10>=3.5,"Good",IF(F10>=2.5,"Low","Needs Improvement")))) -> Exceeds Expectations
E11: جودة حياة المتعلمين Learners’ Wellbeing | F11: =IF(COUNT(التقييم!H31:H33)=0,"",ROUND(SUM(التقييم!H31:H33)/COUNT(التقييم!H31:H33),2)) -> 5 | G11: =IF(F11="","",IF(F11>=4.3,"Exceeds Expectations",IF(F11>=3.5,"Good",IF(F11>=2.5,"Low","Needs Improvement")))) -> Exceeds Expectations
B14: نقاط القوة Strengths | C14: تخطيط جاذب ومنظم للحصة أسهم في تحقيق تعلم متكامل وفعّال. تهيئة مشوقة ومحفزة ساعدت على جذب انتباه الطلبة وبناء دافعية عالية للتعلم. إشراك الطلبة بفاعلية في استنتاج نواتج التعلم والتعبير عنها بوضوح. تمكّن علمي ومهاري عالٍ انعكس في قيادتكم للطلبة نحو فهم متقدم. عرض المحتوى بتسلسل منطقي عزز التحليل والتفكير العالي. ربط التعلم بالحياة الواقعية بصورة داعمة للمعنى والتطبيق. توظيف استراتيجيات وأنشطة تعليمية مؤثرة، مدعومة بأدوات ووسائط رقمية متنوعة. مراعاة الفروق الفردية بفاعلية، بما يضمن مشاركة جميع الطلبة. إدارة صفية متميزة قائمة على علاقات احترام وثقة وانضباط ذاتي. إدارة زمنية دقيقة أسهمت في تحقيق جميع نواتج التعلم. تطبيق تقويم متكامل مع تغذية راجعة عالية الأثر انعكست على أداء الطلبة. استخدام أساليب تحفيزية عالية التأثير عززت الدافعية والتنافس الإيجابي.
B15: التوصيات Recommendations | C15: الاستمرار في توثيق الممارسات التعليمية المتميزة كمرجع مهني على مستوى القسم. تعزيز نشر وتبادل الخبرات مع الزملاء لدعم جودة الممارسات التعليمية على مستوى المدرسة. الاستمرار في تطوير الابتكار في الأنشطة والتقويم لضمان استدامة التميز والتقدم. المشاركة في الجوائز التربوية.

Sheet خطة الدعم والتطوير
A1: خطة الدعم والتطوير Support and Development Plan مدرسة عبدالله بن ناصر الحلقة الثانية بنين Abdullah Bin Nasser Cycle 2 Boys School معلم Teacher
A2: اسم المعلم Teacher Name | B2: رقم الأوراكل Oracle Number | D2: المادة Subject | E2: تاريخ الزيارة Visit Date | F2: الصف والشعبة Grade / Section | G2: الحصة Period
A3: =التقييم!B5 -> رشا احمد محمود عبدالسلام | B3: =التقييم!B7 -> 282439 | D3: =التقييم!B6 -> الفنون البصرية | E3: =التقييم!E6 -> 13/5/2026 | F3: =التقييم!E5 -> ثامن متقدم | G3: =التحليل!H3 -> الثانية
A5: الأولوية Priority | B5: المؤشر Indicator | C5: الدرجة Score | D5: التوصية الفورية Immediate Recommendation | E5: إجراء تنفيذي Action Step | F5: المدة Duration | G5: مؤشر النجاح Success Indicator
A6: أولوية 1 Priority 1 | B6: =IF(ROWS($A$6:A6)>COUNT(التقييم!$J$10:$J$33),"",INDEX(التقييم!$B$10:$B$33,MATCH(ROWS($A$6:A6),التقييم!$J$10:$J$33,0))) | C6: =IF($B6="","",INDEX(التقييم!$H$10:$H$33,MATCH(ROWS($A$6:A6),التقييم!$J$10:$J$33,0))) | D6: =IF($B6="","",IFERROR(VLOOKUP($B6,'بيانات مساعدة'!$A$2:$C$25,2,FALSE),"")) | E6: =IF($B6="","",IFERROR(VLOOKUP($B6,'بيانات مساعدة'!$A$2:$C$25,3,FALSE),"")) | F6: =IF($B6="","","4 weeks") | G6: =IF($B6="","","The indicator improved to level 4 or above in the subsequent visit")
A7: أولوية 2 Priority 2 | B7: =IF(ROWS($A$6:A7)>COUNT(التقييم!$J$10:$J$33),"",INDEX(التقييم!$B$10:$B$33,MATCH(ROWS($A$6:A7),التقييم!$J$10:$J$33,0))) | C7: =IF($B7="","",INDEX(التقييم!$H$10:$H$33,MATCH(ROWS($A$6:A7),التقييم!$J$10:$J$33,0))) | D7: =IF($B7="","",IFERROR(VLOOKUP($B7,'بيانات مساعدة'!$A$2:$C$25,2,FALSE),"")) | E7: =IF($B7="","",IFERROR(VLOOKUP($B7,'بيانات مساعدة'!$A$2:$C$25,3,FALSE),"")) | F7: =IF($B7="","","4 weeks") | G7: =IF($B7="","","The indicator improved to level 4 or above in the subsequent visit")
A8: أولوية 3 Priority 3 | B8: =IF(ROWS($A$6:A8)>COUNT(التقييم!$J$10:$J$33),"",INDEX(التقييم!$B$10:$B$33,MATCH(ROWS($A$6:A8),التقييم!$J$10:$J$33,0))) | C8: =IF($B8="","",INDEX(التقييم!$H$10:$H$33,MATCH(ROWS($A$6:A8),التقييم!$J$10:$J$33,0))) | D8: =IF($B8="","",IFERROR(VLOOKUP($B8,'بيانات مساعدة'!$A$2:$C$25,2,FALSE),"")) | E8: =IF($B8="","",IFERROR(VLOOKUP($B8,'بيانات مساعدة'!$A$2:$C$25,3,FALSE),"")) | F8: =IF($B8="","","4 weeks") | G8: =IF($B8="","","The indicator improved to level 4 or above in the subsequent visit")
A9: أولوية 4 Priority 4 | B9: =IF(ROWS($A$6:A9)>COUNT(التقييم!$J$10:$J$33),"",INDEX(التقييم!$B$10:$B$33,MATCH(ROWS($A$6:A9),التقييم!$J$10:$J$33,0))) | C9: =IF($B9="","",INDEX(التقييم!$H$10:$H$33,MATCH(ROWS($A$6:A9),التقييم!$J$10:$J$33,0))) | D9: =IF($B9="","",IFERROR(VLOOKUP($B9,'بيانات مساعدة'!$A$2:$C$25,2,FALSE),"")) | E9: =IF($B9="","",IFERROR(VLOOKUP($B9,'بيانات مساعدة'!$A$2:$C$25,3,FALSE),"")) | F9: =IF($B9="","","4 weeks") | G9: =IF($B9="","","The indicator improved to level 4 or above in the subsequent visit")
A10: أولوية 5 Priority 5 | B10: =IF(ROWS($A$6:A10)>COUNT(التقييم!$J$10:$J$33),"",INDEX(التقييم!$B$10:$B$33,MATCH(ROWS($A$6:A10),التقييم!$J$10:$J$33,0))) | C10: =IF($B10="","",INDEX(التقييم!$H$10:$H$33,MATCH(ROWS($A$6:A10),التقييم!$J$10:$J$33,0))) | D10: =IF($B10="","",IFERROR(VLOOKUP($B10,'بيانات مساعدة'!$A$2:$C$25,2,FALSE),"")) | E10: =IF($B10="","",IFERROR(VLOOKUP($B10,'بيانات مساعدة'!$A$2:$C$25,3,FALSE),"")) | F10: =IF($B10="","","4 weeks") | G10: =IF($B10="","","The indicator improved to level 4 or above in the subsequent visit")
A11: أولوية 6 Priority 6 | B11: =IF(ROWS($A$6:A11)>COUNT(التقييم!$J$10:$J$33),"",INDEX(التقييم!$B$10:$B$33,MATCH(ROWS($A$6:A11),التقييم!$J$10:$J$33,0))) | C11: =IF($B11="","",INDEX(التقييم!$H$10:$H$33,MATCH(ROWS($A$6:A11),التقييم!$J$10:$J$33,0))) | D11: =IF($B11="","",IFERROR(VLOOKUP($B11,'بيانات مساعدة'!$A$2:$C$25,2,FALSE),"")) | E11: =IF($B11="","",IFERROR(VLOOKUP($B11,'بيانات مساعدة'!$A$2:$C$25,3,FALSE),"")) | F11: =IF($B11="","","4 weeks") | G11: =IF($B11="","","The indicator improved to level 4 or above in the subsequent visit")
A12: أولوية 7 Priority 7 | B12: =IF(ROWS($A$6:A12)>COUNT(التقييم!$J$10:$J$33),"",INDEX(التقييم!$B$10:$B$33,MATCH(ROWS($A$6:A12),التقييم!$J$10:$J$33,0))) | C12: =IF($B12="","",INDEX(التقييم!$H$10:$H$33,MATCH(ROWS($A$6:A12),التقييم!$J$10:$J$33,0))) | D12: =IF($B12="","",IFERROR(VLOOKUP($B12,'بيانات مساعدة'!$A$2:$C$25,2,FALSE),"")) | E12: =IF($B12="","",IFERROR(VLOOKUP($B12,'بيانات مساعدة'!$A$2:$C$25,3,FALSE),"")) | F12: =IF($B12="","","4 weeks") | G12: =IF($B12="","","The indicator improved to level 4 or above in the subsequent visit")
A13: أولوية 8 Priority 8 | B13: =IF(ROWS($A$6:A13)>COUNT(التقييم!$J$10:$J$33),"",INDEX(التقييم!$B$10:$B$33,MATCH(ROWS($A$6:A13),التقييم!$J$10:$J$33,0))) | C13: =IF($B13="","",INDEX(التقييم!$H$10:$H$33,MATCH(ROWS($A$6:A13),التقييم!$J$10:$J$33,0))) | D13: =IF($B13="","",IFERROR(VLOOKUP($B13,'بيانات مساعدة'!$A$2:$C$25,2,FALSE),"")) | E13: =IF($B13="","",IFERROR(VLOOKUP($B13,'بيانات مساعدة'!$A$2:$C$25,3,FALSE),"")) | F13: =IF($B13="","","4 weeks") | G13: =IF($B13="","","The indicator improved to level 4 or above in the subsequent visit")
A14: أولوية 9 Priority 9 | B14: =IF(ROWS($A$6:A14)>COUNT(التقييم!$J$10:$J$33),"",INDEX(التقييم!$B$10:$B$33,MATCH(ROWS($A$6:A14),التقييم!$J$10:$J$33,0))) | C14: =IF($B14="","",INDEX(التقييم!$H$10:$H$33,MATCH(ROWS($A$6:A14),التقييم!$J$10:$J$33,0))) | D14: =IF($B14="","",IFERROR(VLOOKUP($B14,'بيانات مساعدة'!$A$2:$C$25,2,FALSE),"")) | E14: =IF($B14="","",IFERROR(VLOOKUP($B14,'بيانات مساعدة'!$A$2:$C$25,3,FALSE),"")) | F14: =IF($B14="","","4 weeks") | G14: =IF($B14="","","The indicator improved to level 4 or above in the subsequent visit")
